<?xml version='1.0'?>
<sdf version='1.4'>
    <model name="olfactoBot">
        <static>false</static>
        <link name='chassis'>
            <pose>0 0 .1 0 0 0</pose>

            <inertial>
                <mass>5.67</mass>
                <inertia>
                    <ixx>0.07</ixx>
                    <iyy>0.08</iyy>
                    <izz>0.10</izz>
                    <ixy>0</ixy>
                    <ixz>0</ixz>
                    <iyz>0</iyz>
                </inertia>
            </inertial>
            <collision name='collision'>
                <geometry>
                    <box>
                        <size>.4 .2 .1</size>
                    </box>
                </geometry>
            </collision>

            <visual name='visual'>
                <pose>0 0 0.065 0 0 0</pose>
                <geometry>
                    <mesh>
                        <uri>model://pioneer2dx/meshes/chassis.dae</uri>
                        <scale>0.9 0.7 0.7</scale>
                    </mesh>
                </geometry>
            </visual>
            <collision name='caster_collision'>
                <pose>-0.15 0 -0.05 0 0 0</pose>
                <geometry>
                    <sphere>
                        <radius>.05</radius>
                    </sphere>
                </geometry>

                <surface>
                    <friction>
                        <ode>
                            <mu>0</mu>
                            <mu2>0</mu2>
                            <slip1>1.0</slip1>
                            <slip2>1.0</slip2>
                        </ode>
                    </friction>
                </surface>
            </collision>

            <visual name='caster_visual'>
                <pose>-0.15 0 -0.05 0 0 0</pose>
                <geometry>
                    <sphere>
                        <radius>.05</radius>
                    </sphere>
                </geometry>
                <material>
                    <script>
                        <uri>file://media/materials/scripts/gazebo.material</uri>
                        <name>Gazebo/FlatBlack</name>
                    </script>
                </material>
            </visual>
        </link>
        <link name="left_wheel">
            <pose>0.1 0.13 0.1 0 1.5707 1.5707</pose>
            <collision name="collision">
                <geometry>
                    <cylinder>
                        <radius>.1</radius>
                        <length>.05</length>
                    </cylinder>
                </geometry>
            </collision>
            <visual name="visual">
                <geometry>
                    <cylinder>
                        <radius>.1</radius>
                        <length>.05</length>
                    </cylinder>
                </geometry>
                <material>
                    <script>
                        <uri>file://media/materials/scripts/gazebo.material</uri>
                        <name>Gazebo/FlatBlack</name>
                    </script>
                </material>
            </visual>
        </link>
        <link name="right_wheel">
            <pose>0.1 -0.13 0.1 0 1.5707 1.5707</pose>
            <collision name="collision">
                <geometry>
                    <cylinder>
                        <radius>.1</radius>
                        <length>.05</length>
                    </cylinder>
                </geometry>
            </collision>
            <visual name="visual">
                <geometry>
                    <cylinder>
                        <radius>.1</radius>
                        <length>.05</length>
                    </cylinder>
                </geometry>
                <material>
                    <script>
                        <uri>file://media/materials/scripts/gazebo.material</uri>
                        <name>Gazebo/FlatBlack</name>
                    </script>
                </material>
            </visual>
        </link>
        <joint type="revolute" name="left_wheel_hinge">
            <pose>0 0 -0.03 0 0 0</pose>
            <child>left_wheel</child>
            <parent>chassis</parent>
            <axis>
                <xyz>0 1 0</xyz>
            </axis>
        </joint>

        <joint type="revolute" name="right_wheel_hinge">
            <pose>0 0 0.03 0 0 0</pose>
            <child>right_wheel</child>
            <parent>chassis</parent>
            <axis>
                <xyz>0 1 0</xyz>
            </axis>
        </joint>
        <include>
            <uri>model://hokuyo</uri>
            <pose>0.2 0 0.2 0 0 0</pose>
        </include>
        <joint name="hokuyo_joint" type="revolute">
            <child>hokuyo::link</child>
            <parent>chassis</parent>
            <axis>
                <xyz>0 0 1</xyz>
                <limit>
                    <upper>0</upper>
                    <lower>0</lower>
                </limit>
            </axis>
        </joint>

    </model>
</sdf>

